Workbook

Sheet ERP_Cleaned
A1: RAW_PO_NUMBER | B1: TRANSACTION_DATE | C1: DEPARTMENT_NAME | D1: EXPENSE_CATEGORY | E1: VENDOR_NAME | F1: RAW_AMOUNT | G1: GL_CODE | H1: TAX_RATE | I1: APPROVAL_STATUS | J1: INVOICE_REF | K1: SYSTEM_COMMENTS
A2: PO-2024-2002 | B2: 45932 | C2: Facilities & Ops | D2: Travel & Entertainment | E2: Prime Space Realty | F2: 115160.76 | G2: GL-500100 | H2: 12% | I2: APPROVED | K2: System Auto-Generated
A3: PO-2024-2006 | B3: 45908 | C3: IT Operations | D3: Office Supplies | E3: CloudSaaS Corp | F3: 186051.69 | G3: GL-500100 | H3: 12% | I3: APPROVED | J3: INV-5166 | K3: System Auto-Generated
A4: PO-2024-2008 | B4: 45954 | C4: Marketing & Sales | D4: Digital Advertising | E4: PaperCorp Supplies | F4: 113149.23 | G4: GL-500200 | H4: 12% | I4: APPROVED | J4: INV-8892 | K4: Urgent operational requirement!
A5: PO-2024-2016 | B5: 45946 | C5: Facilities & Ops | D5: Office Supplies | E5: Prime Space Realty | F5: 206325.42 | G5: GL-500100 | H5: 12% | I5: APPROVED | J5: INV-8900 | K5: System Auto-Generated
A6: PO-2024-2017 | B6: 45069 | C6: IT Operations | D6: Digital Advertising | E6: CloudSaaS Corp | F6: 57783.36 | G6: GL-500100 | H6: 0% | I6: APPROVED | J6: INV-5544 | K6: System Auto-Generated
A7: PO-2024-2018 | B7: 44968 | C7: Marketing & Sales | D7: Office Rent | E7: Prime Space Realty | F7: 51244.28 | G7: GL-600300 | H7: 12% | I7: APPROVED | J7: INV-7194 | K7: Urgent operational requirement!
B8: 45117 | C8: Facilities & Ops | D8: Office Rent | E8: GlobalMedia Ads | F8: 92128.53 | G8: GL-600300 | H8: 12% | I8: APPROVED | J8: INV-8603 | K8: System Auto-Generated
A9: PO-2024-2023 | B9: 45467 | C9: IT Operations | D9: Digital Advertising | E9: TechDistributors Inc | F9: 36320.02 | G9: GL-500100 | H9: 12% | I9: APPROVED | K9: System Auto-Generated
A10: PO-2024-2026 | B10: 45004 | C10: Facilities & Ops | D10: Cloud Infrastructure | E10: Prime Space Realty | F10: 50577.43 | G10: GL-500200 | H10: 12% | I10: APPROVED | J10: INV-9582 | K10: System Auto-Generated
A11: PO-2024-2027 | B11: 45442 | C11: Facilities & Ops | D11: Cloud Infrastructure | E11: GlobalMedia Ads | F11: 17764.09 | G11: GL-600300 | H11: 12% | I11: APPROVED | J11: INV-9956 | K11: System Auto-Generated
A12: PO-2024-2030 | B12: 45699 | C12: Marketing & Sales | D12: Travel & Entertainment | E12: PaperCorp Supplies | F12: 170659.31 | G12: GL-500100 | H12: 12% | I12: APPROVED | J12: INV-9601 | K12: System Auto-Generated
A13: PO-2024-2035 | B13: 45767 | C13: Marketing & Sales | D13: Digital Advertising | E13: CloudSaaS Corporation | F13: 242782.85 | G13: GL-600300 | H13: 12% | I13: APPROVED | K13: System Auto-Generated
A14: PO-2024-2040 | B14: 44931 | C14: Facilities & Ops | D14: Cloud Infrastructure | E14: CloudSaaS Corp | F14: 83487.25 | G14: GL-500100 | H14: 12% | I14: APPROVED | J14: INV-7969 | K14: Urgent operational requirement!
A15: PO-2024-2044 | B15: 45640 | C15: Facilities & Ops | D15: Travel & Entertainment | E15: GlobalMedia Ads | F15: 134858 | G15: GL-600300 | H15: 12% | I15: APPROVED | J15: INV-5045 | K15: System Auto-Generated
A16: PO-2024-2050 | B16: 44950 | C16: Unassigned | D16: Hardware Procurement | E16: GlobalMedia Ads | F16: 214019.64 | G16: GL-500200 | H16: 12% | I16: APPROVED | K16: System Auto-Generated
A17: PO-2024-2055 | B17: 45592 | C17: Facilities & Ops | D17: Cloud Infrastructure | E17: GlobalMedia Ads | F17: 88319.3 | G17: GL-500100 | H17: 12% | I17: APPROVED | J17: INV-8325 | K17: System Auto-Generated
A18: PO-2024-2056 | B18: 45711 | C18: Marketing & Sales | D18: Software Licenses | E18: Prime Space Realty | F18: 250076.66 | G18: GL-500100 | H18: 12% | I18: APPROVED | J18: INV-5036 | K18: System Auto-Generated
A19: PO-2024-2058 | B19: 45314 | C19: Marketing & Sales | D19: Office Supplies | E19: Prime Space Realty | F19: 168739.9 | G19: GL-500100 | H19: 12% | I19: APPROVED | J19: INV-8693 | K19: System Auto-Generated
A20: PO-2024-2060 | B20: 45307 | C20: Marketing & Sales | D20: Hardware Procurement | E20: PaperCorp Supplies | F20: 153905 | G20: GL-500200 | H20: 12% | I20: APPROVED | J20: INV-8446 | K20: System Auto-Generated
A21: PO-2024-2061 | B21: 45760 | C21: Marketing & Sales | D21: Cloud Infrastructure | E21: TechDistributors Inc | F21: 183744.55 | G21: GL-500100 | H21: 12% | I21: APPROVED | J21: INV-9772 | K21: Urgent operational requirement!
A22: PO-2024-2062 | B22: 45453 | C22: HR & Admin | D22: Travel & Entertainment | E22: CloudSaaS Corp | F22: 42533.69 | G22: GL-500100 | H22: 12% | I22: APPROVED | J22: INV-5398 | K22: System Auto-Generated
A23: PO-2024-2064 | B23: 45829 | C23: IT Operations | D23: Office Supplies | E23: PaperCorp Supplies | F23: 34540.36 | G23: GL-500100 | H23: 12% | I23: APPROVED | J23: INV-9562 | K23: System Auto-Generated
A24: PO-2024-2067 | B24: 45221 | C24: IT Operations | D24: Hardware Procurement | E24: GlobalMedia Ads | F24: 128124.55 | G24: GL-600300 | H24: 12% | I24: APPROVED | J24: INV-6672 | K24: System Auto-Generated
A25: PO-2024-2068 | B25: 45088 | C25: Facilities & Ops | D25: Digital Advertising | E25: GlobalMedia Ads | F25: 121957.05 | G25: GL-600300 | H25: 12% | I25: APPROVED | J25: INV-4659 | K25: System Auto-Generated
A26: PO-2024-2070 | B26: 45202 | C26: IT Operations | D26: Software Licenses | E26: PaperCorp Supplies | F26: 29801.85 | G26: GL-600300 | H26: 12% | I26: APPROVED | J26: INV-4582 | K26: System Auto-Generated
A27: PO-2024-2071 | B27: 45993 | C27: IT Operations | D27: Office Rent | E27: GlobalMedia Ads | F27: 311092.01 | G27: GL-500200 | H27: 12% | I27: APPROVED | J27: INV-9656 | K27: System Auto-Generated
A28: PO-2024-2072 | B28: 45415 | C28: IT Operations | D28: Travel & Entertainment | E28: GlobalMedia Ads | F28: 127541.66 | G28: GL-500200 | H28: 12% | I28: APPROVED | J28: INV-8819 | K28: System Auto-Generated
... A30: PO-2024-2074 | B30: 45994 | C30: HR & Admin | D30: Cloud Infrastructure | E30: PaperCorp Supplies | F30: 298392.91 | G30: GL-600300 | H30: 0% | I30: APPROVED | J30: INV-7018 | K30: System Auto-Generated
A31: PO-2024-2076 | B31: 45464 | C31: Facilities & Ops | D31: Travel & Entertainment | E31: TechDistributors Inc | F31: 126727.01 | G31: GL-500200 | H31: 0% | I31: APPROVED | K31: System Auto-Generated
A32: PO-2024-2077 | B32: 45163 | C32: Facilities & Ops | D32: Office Supplies | E32: CloudSaaS Corporation | F32: 80824.49 | G32: GL-600300 | H32: 12% | I32: APPROVED | J32: INV-5556 | K32: System Auto-Generated
A33: PO-2024-2078 | B33: 45913 | C33: IT Operations | D33: Cloud Infrastructure | E33: CloudSaaS Corp | F33: 58524.65 | G33: GL-500100 | H33: 12% | I33: APPROVED | J33: INV-7861 | K33: System Auto-Generated
A34: PO-2024-2079 | B34: 45073 | C34: Marketing & Sales | D34: Office Rent | E34: Prime Space Realty | F34: 40200.79 | G34: GL-600300 | H34: 12% | I34: APPROVED | K34: System Auto-Generated
A35: PO-2024-2080 | B35: 45731 | C35: Facilities & Ops | D35: Software Licenses | E35: TechDistributors Inc | F35: 12518.53 | G35: GL-500200 | H35: 12% | I35: APPROVED | J35: INV-5405 | K35: System Auto-Generated
A36: PO-2024-2084 | B36: 45414 | C36: IT Operations | D36: Digital Advertising | E36: TechDistributors Inc | F36: 280488.2 | G36: GL-600300 | H36: 12% | I36: APPROVED | J36: INV-4233 | K36: System Auto-Generated
A37: PO-2024-2085 | B37: 45286 | C37: Marketing & Sales | D37: Digital Advertising | E37: Prime Space Realty | F37: 33710.14 | G37: GL-600300 | H37: 12% | I37: APPROVED | J37: INV-9424 | K37: System Auto-Generated
A38: PO-2024-2087 | B38: 44937 | C38: Facilities & Ops | D38: Office Supplies | E38: CloudSaaS Corp | F38: 24786.39 | G38: GL-500200 | H38: 12% | I38: APPROVED | J38: INV-7594 | K38: System Auto-Generated
A39: PO-2024-2088 | B39: 45536 | C39: HR & Admin | D39: Digital Advertising | E39: Prime Space Realty | F39: 100068 | G39: GL-500200 | H39: 12% | I39: APPROVED | J39: INV-5675 | K39: Urgent operational requirement!
A40: PO-2024-2089 | B40: 45530 | C40: Marketing & Sales | D40: Travel & Entertainment | E40: PaperCorp Supplies | F40: 56772.71 | G40: GL-600300 | H40: 12% | I40: APPROVED | J40: INV-5052 | K40: System Auto-Generated
A41: PO-2024-2095 | B41: 45367 | C41: Marketing & Sales | D41: Digital Advertising | E41: Prime Space Realty | F41: 96138.43 | G41: GL-500100 | H41: 12% | I41: APPROVED | J41: INV-4831 | K41: System Auto-Generated
...

Sheet Dim_Budgets
A1: Fiscal_Year | B1: Department | C1: Allocated_Budget_PHP
A2: 2023 | B2: IT Operations | C2: 6500000
A3: 2023 | B3: Marketing & Sales | C3: 5200000
A4: 2023 | B4: HR & Admin | C4: 4100000
A5: 2023 | B5: Facilities & Ops | C5: 5800000
A6: 2024 | B6: IT Operations | C6: 6890000
A7: 2024 | B7: Marketing & Sales | C7: 5510000
A8: 2024 | B8: HR & Admin | C8: 4340000
A9: 2024 | B9: Facilities & Ops | C9: 6140000
A10: 2025 | B10: IT Operations | C10: 7300000
A11: 2025 | B11: Marketing & Sales | C11: 5840000
A12: 2025 | B12: HR & Admin | C12: 4600000
A13: 2025 | B13: Facilities & Ops | C13: 6500000

Sheet Sheet1
A1: Row Labels | B1: Sum of RAW_AMOUNT
A2: <05/01/2023 | D2: Budget | E2: Variance
A3: 2023 | B3: 23139384 | D3: =SUM(D4:D8) -> 21600000 | I3: % | K3: Dept | L3: Total Budget | M3: Total Expenditure | N3: Variance | O3: Variance % | P3: Overspend | Q3: Variance
A4: Facilities & Ops | B4: 6190664.8 | C4: 6190664.8 | D4: =_xlfn.XLOOKUP(A4,Dim_Budgets!$B$2:$B$5,Dim_Budgets!$C$2:$C$5) -> 5800000 | E4: =D4-C4 -> -390664.82 | G4: Total Variance | H4: =SUM(E4:E20) -> -9344600.1 | I4: =H4/D21 -> -0.13598079 | K4: Facilities & Ops | L4: =SUMIFS($D$4:$D$20,$A$4:$A$20,K4) -> 18440000 | M4: =SUMIFS($B$4:$B$20,$A$4:$A$20,K4) -> 22656061 | N4: =L4-M4 -> -4216061.2 | O4: =N4/L4 -> -0.22863672 | P4: =SUMIFS($E$4:$E$20,$A$4:$A$20,K4,$E$4:$E$20,"<0") -> -4216061.2 | Q4: =P4/L4 -> -0.22863672
A5: HR & Admin | B5: 2251691.5 | C5: 2251691.5 | D5: =_xlfn.XLOOKUP(A5,Dim_Budgets!$B$2:$B$5,Dim_Budgets!$C$2:$C$5) -> 4100000 | E5: =D5-C5 -> 1848308.5 | G5: Overspend Total | H5: =SUMIF(E4:E20,"<0") -> -13135835 | I5: =H5/D21 -> -0.1911501 | K5: HR & Admin | L5: =SUMIFS($D$4:$D$20,$A$4:$A$20,K5) -> 13040000 | M5: =SUMIFS($B$4:$B$20,$A$4:$A$20,K5) -> 9550675.7 | N5: =L5-M5 -> 3489324.3 | O5: =N5/L5 -> 0.26758622 | P5: =SUMIFS($E$4:$E$20,$A$4:$A$20,K5,$E$4:$E$20,"<0") -> 0 | Q5: =P5/L5 -> 0
A6: IT Operations | B6: 7988971.4 | C6: 7988971.4 | D6: =_xlfn.XLOOKUP(A6,Dim_Budgets!$B$2:$B$5,Dim_Budgets!$C$2:$C$5) -> 6500000 | E6: =D6-C6 -> -1488971.4 | G6: Approved Budget | H6: =D21 -> 68720000 | K6: IT Operations | L6: =SUMIFS($D$4:$D$20,$A$4:$A$20,K6) -> 20690000 | M6: =SUMIFS($B$4:$B$20,$A$4:$A$20,K6) -> 21877061 | N6: =L6-M6 -> -1187061.1 | O6: =N6/L6 -> -0.057373666 | P6: =SUMIFS($E$4:$E$20,$A$4:$A$20,K6,$E$4:$E$20,"<0") -> -1488971.4 | Q6: =P6/L6 -> -0.071965754
A7: Marketing & Sales | B7: 5594418.6 | C7: 5594418.6 | D7: =_xlfn.XLOOKUP(A7,Dim_Budgets!$B$2:$B$5,Dim_Budgets!$C$2:$C$5) -> 5200000 | E7: =D7-C7 -> -394418.6 | G7: Total Expenditures | H7: =GETPIVOTDATA("RAW_AMOUNT",$A$1) -> 78064600 | K7: Marketing & Sales | L7: =SUMIFS($D$4:$D$20,$A$4:$A$20,K7) -> 16550000 | M7: =SUMIFS($B$4:$B$20,$A$4:$A$20,K7) -> 21019775 | N7: =L7-M7 -> -4469775.4 | O7: =N7/L7 -> -0.27007707 | P7: =SUMIFS($E$4:$E$20,$A$4:$A$20,K7,$E$4:$E$20,"<0") -> -4469775.4 | Q7: =P7/L7 -> -0.27007707
A8: Unassigned | B8: 1113637.3 | C8: 1113637.3 | E8: =D8-C8 -> -1113637.3 | K8: Unassigned | L8: =SUMIFS($D$4:$D$20,$A$4:$A$20,K8) -> 0 | M8: =SUMIFS($B$4:$B$20,$A$4:$A$20,K8) -> 2961026.7 | N8: =L8-M8 -> -2961026.7 | O8: =M8/L8 -> #DIV/0! | P8: =SUMIFS($E$4:$E$20,$A$4:$A$20,K8,$E$4:$E$20,"<0") -> -2961026.7 | Q8: =P8/L8 -> #DIV/0!
A9: 2024 | B9: 28451017 | D9: =SUM(D10:D14) -> 22880000
A10: Facilities & Ops | B10: 8618590.6 | C10: 8618590.6 | D10: =_xlfn.XLOOKUP(A10,Dim_Budgets!$B$6:$B$9,Dim_Budgets!$C$6:$C$9) -> 6140000 | E10: =D10-C10 -> -2478590.6
A11: HR & Admin | B11: 3493418.2 | C11: 3493418.2 | D11: =_xlfn.XLOOKUP(A11,Dim_Budgets!$B$6:$B$9,Dim_Budgets!$C$6:$C$9) -> 4340000 | E11: =D11-C11 -> 846581.75
A12: IT Operations | B12: 6640728.1 | C12: 6640728.1 | D12: =_xlfn.XLOOKUP(A12,Dim_Budgets!$B$6:$B$9,Dim_Budgets!$C$6:$C$9) -> 6890000 | E12: =D12-C12 -> 249271.89
A13: Marketing & Sales | B13: 9007624.5 | C13: 9007624.5 | D13: =_xlfn.XLOOKUP(A13,Dim_Budgets!$B$6:$B$9,Dim_Budgets!$C$6:$C$9) -> 5510000 | E13: =D13-C13 -> -3497624.5
A14: Unassigned | B14: 690655.09 | C14: 690655.09 | E14: =D14-C14 -> -690655.09
A15: 2025 | B15: 26474200 | D15: =SUM(D16:D20) -> 24240000 | G15: Budget | H15: Actual Spend
A16: Facilities & Ops | B16: 7846805.7 | C16: 7846805.7 | D16: =_xlfn.XLOOKUP(A16,Dim_Budgets!$B$10:$B$13,Dim_Budgets!$C$10:$C$13) -> 6500000 | E16: =D16-C16 -> -1346805.7 | G16: 21600000 | H16: 23139384
A17: HR & Admin | B17: 3805565.9 | C17: 3805565.9 | D17: =_xlfn.XLOOKUP(A17,Dim_Budgets!$B$10:$B$13,Dim_Budgets!$C$10:$C$13) -> 4600000 | E17: =D17-C17 -> 794434.15 | G17: 22880000 | H17: 28451017
A18: IT Operations | B18: 7247361.6 | C18: 7247361.6 | D18: =_xlfn.XLOOKUP(A18,Dim_Budgets!$B$10:$B$13,Dim_Budgets!$C$10:$C$13) -> 7300000 | E18: =D18-C18 -> 52638.4 | G18: 24240000 | H18: 26474200
A19: Marketing & Sales | B19: 6417732.4 | C19: 6417732.4 | D19: =_xlfn.XLOOKUP(A19,Dim_Budgets!$B$10:$B$13,Dim_Budgets!$C$10:$C$13) -> 5840000 | E19: =D19-C19 -> -577732.36
A20: Unassigned | B20: 1156734.3 | C20: 1156734.3 | E20: =D20-C20 -> -1156734.3
A21: Grand Total | B21: 78064600 | C21: =SUM(C4:C20) -> 78064600 | D21: =SUM(D3,D9,D15) -> 68720000 | E21: =D21-GETPIVOTDATA("RAW_AMOUNT",$A$1) -> -9344600.1
